Workbook

Sheet Start Here
A1: Alpha Nodus — Social Media Performance & Demo Attribution Tracker
A2: Built for LinkedIn (company + founder), Instagram, X (plus Facebook / YouTube if you use them). Audience: independent imaging & radiology centers, USA.
B5: What this workbook answers
C6: 1. Which platform, content pillar, case study, format, hook and persona gets the best reach and engagement?
C7: 2. Which posts actually send imaging-center decision-makers to alphanodus.com, to the demo page, and into a booked demo?
C8: 3. What does each demo cost (if boosted) and how much pipeline did each post / case study create?
B10: Colour legend
B11: Input | C11: Yellow cell = you type here (or pick from the dropdown).
B12: Calculated | C12: Grey cell = formula. Don't type over it — it recalculates by itself.
B13: Public data | C13: Blue text = September 2026 data pulled from Alpha Nodus's public LinkedIn, Instagram and X pages on 28 Sep 2026. Overwrite with native-analytics numbers when you have them.
C14: Hover over any column header with a red corner triangle for a note on what to enter.
B16: Sheet map
B17: Post Tracker | C17: One row per post per platform. Details → auto tracking link → platform metrics → auto reach & engagement → website/demo funnel.
B18: Demo Pipeline | C18: One row per demo booked from ANY source. Its UTM / manual Post ID links the demo back to the post automatically.
B19: Dashboard | C19: Pick a date range. Headline KPIs, funnel, top 5 posts, and breakdowns by platform, account, pillar, case study, format, persona, hook, CTA, link placement, weekday, paid vs organic, monthly trend and demo sources.
B20: Case Studies | C20: Library of case studies (name, slug, client type, problem, result). Shows all-time reach, engagement and demos for each story.
B21: Follower Growth | C21: Weekly follower count per account → net new followers.
B22: Tracking Setup | C22: UTM rules, where each number comes from (GA4 paths), website set-up checklist, and every attribution scenario.
B23: Metric Definitions | C23: Exact formula for every calculated metric and platform-by-platform notes.
B24: Settings | C24: Dropdown lists, default landing page and engagement weights. Add new pillars / formats / personas here.
B26: Workflow
B27: Before posting | C27: Add a row: date, time, platform, account, format, pillar, case study, topic, hook, persona, CTA. The Post ID and Tracking URL appear automatically.
C28: Copy the Tracking URL (or shorten it and paste the short link in the Short Link column) and use it as the ONLY link in the post / first comment / bio / story sticker.
B29: Right after posting | C29: Paste the Live Post URL and the account's current follower count.
B30: Day 7 after posting | C30: Open the platform's post analytics and fill the purple Platform Metrics block. Always pull at the same age so posts compare fairly. Count ICP engagers.
B31: Weekly (Mondays) | C31: GA4 → fill Sessions, Engaged Sessions, Demo Page Visits for each post (see Tracking Setup). Update Follower Growth.
B32: Every demo booked | C32: Add a row to Demo Pipeline with the utm_* values from the form / CRM and the 'How did you hear about us?' answer. Update status, qualified and stage as it progresses.
B33: Monthly review | C33: Dashboard: which pillar / case study / format has the highest engagement rate AND demos? Write 'What We Learned' + 'Next Action' on the best and worst posts. Scale winners, retire losers.
B35: Data notes — September 2026 (pulled 28 Sep 2026)
B36: Accounts | C36: LinkedIn company page (2,640 followers), Instagram @alphanodus (61), X @AlphaNodus (46). No founder / employee accounts were included — add them as Account = Founder / Employee.
B37: What was found | C37: 13 posts: 5 LinkedIn (Sep 11, 14, 18, 23, 28), 4 Instagram and 4 X (Sep 11, 14, 18, 23 — the same four stories cross-posted). X and Instagram had no posts Sep 1–10; LinkedIn's public page only lists its 5 newest posts, so check LinkedIn for anything posted Sep 1–10.
B38: What's public | C38: LinkedIn & Instagram: likes/reactions and comments only. X: replies and views (used as impressions). Everything else (impressions, reach, saves, shares, clicks, profile visits) is only in each platform's own analytics — fill those yellow cells from there.
B39: Engagement rate | C39: Because LinkedIn / Instagram impressions aren't public, compare posts on 'Engagement Rate (by Followers)' until impressions are entered; then switch to 'Engagement Rate (by Reach)'.
B40: Website & demos | C40: The September posts didn't use UTM links, so website sessions and demos can't be traced to them. Start using each row's Tracking URL from the next post onward, and log every demo on Demo Pipeline.
B42: Rules that keep the data clean
C43: • Every post gets its own tracking link — never reuse a link across posts or platforms (the Post ID is the link's fingerprint).
C44: • Post ID = platform code + account code + date + time (e.g. LIC-260922-0900). A red Post ID means a duplicate — change the time by a minute.
C45: • Never put UTM links on alphanodus.com's own internal links — it resets the visitor's source.
C46: • One post published on 3 platforms = 3 rows (each gets its own link), sharing the same case study so they roll up together.
C47: • Judge a post on engagement rate (not raw likes) and on demos; judge a case study only after it has run on at least 2–3 posts.

Sheet Post Tracker
A1: Post Tracker — one row per post, per platform
A2: Yellow = you fill in · Grey = calculated, don't type over · Blue = September 2026 posts pulled from public profiles on 9/28 (see Start Here → Data notes).
A3: POST DETAILS | T3: TRACKING LINK (UTM) | AB3: PLATFORM METRICS (enter ~7 days after posting) | AO3: REACH & ENGAGEMENT (calculated) | AZ3: WEBSITE & DEMO FUNNEL | BN3: LEARNINGS | BP3: HELPERS (Dashboard)
A4: Post ID | B4: Publish Date | C4: Publish Time | D4: Day | E4: Week Of (Mon) | F4: Month | G4: Platform | H4: Account | I4: Post Format | J4: Content Pillar | K4: Case Study Featured | L4: Topic / Headline / First Line | M4: Hook Type | N4: Target Persona | O4: CTA | P4: Organic / Paid | Q4: Ad Spend ($) | R4: Live Post URL | S4: Followers at Posting | T4: Landing Page URL | U4: Link Placement | V4: utm_source | W4: utm_medium | X4: utm_campaign | Y4: utm_content | Z4: Tracking URL (copy into post) | AA4: Short Link (optional) | AB4: Data Pulled On | AC4: Impressions / Views | AD4: Reach (Reported) | AE4: Video Views | AF4: Likes / Reactions | AG4: Comments | AH4: Shares / Reposts | AI4: Saves / Bookmarks | AJ4: Link Clicks | AK4: Profile Visits | AL4: New Followers | AM4: ICP Engagers | AN4: Inbound DMs / Conversations | AO4: Reach (Calc.) | AP4: Reach Basis | AQ4: Reach % of Followers | AR4: Total Engagements | AS4: Engagement Rate (by Reach) | AT4: Engagement Rate (by Impr.) | AU4: Engagement Rate (by Followers) | AV4: Click-Through Rate | AW4: Share Rate | AX4: Weighted Eng. per 1K Reach | AY4: ER vs Platform Avg | AZ4: Website Sessions (GA4) | BA4: Engaged Sessions (GA4) | BB4: Demo Page Visits | BC4: Demo Form Starts (optional) | BD4: Demos Booked | BE4: Demos Attended | BF4: Qualified Demos | BG4: Deals Won | BH4: Pipeline Value ($) | BI4: Click → Session % | BJ4: Session → Demo Page % | BK4: Demo Page → Booked % | BL4: Session → Booked % | BM4: Cost per Demo ($) | BN4: What We Learned | BO4: Next Action | BP4: Engagements (posts with reach) | BQ4: Followers (posts with engagement data) | BR4: Rank Key: ER | BS4: Rank Key: Demos
A5: =IF(OR(B5="",G5="",H5=""),"",IFERROR(INDEX(Settings!$E$5:$E$49,MATCH(G5,Settings!$D$5:$D$49,0))&INDEX(Settings!$H$5:$H$47,MATCH(H5,Settings!$G$5:$G$47,0))&"-"&TEXT(B5,"yymmdd")&"-"&IF(C5="","0000",TEXT(C5,"hhmm")),"CHECK LISTS")) -> LIC-260911-1127 | B5: 46276 | C5: 0.47708333 | D5: =IF(B5="","",TEXT(B5,"ddd")) -> Fri | E5: =IF(B5="","",B5-WEEKDAY(B5,3)) -> 46272 | F5: =IF(B5="","",TEXT(B5,"yyyy-mm")) -> 2026-09 | G5: LinkedIn | H5: Company Page | I5: Long Video | J5: Product Demo / Feature | L5: Is your imaging center still running on fax, phones and payer portals? (3-min Gravity AI explainer video) | M5: Question | N5: Owner / CEO | O5: Book a Demo | P5: Organic | R5: https://www.linkedin.com/posts/alphanodus_is-your-imaging-center-stuck-in-the-past-activity-7504198831056764928-9QXW | S5: 2640 | U5: In Post Body | V5: =IF(A5="","",IFERROR(INDEX(Settings!$F$5:$F$49,MATCH(G5,Settings!$D$5:$D$49,0)),"")) -> linkedin | W5: =IF(A5="","",IF(OR(P5="",P5="Organic"),"social","paid_social")) -> social | X5: =IF(A5="","",IF(K5<>"",IFERROR(INDEX('Case Studies'!$C$5:$C$54,MATCH(K5,'Case Studies'!$B$5:$B$54,0))&"","case-study"),IF(J5<>"",IFERROR(INDEX(Settings!$J$5:$J$55,MATCH(J5,Settings!$I$5:$I$55,0)),"general"),"general"))) -> product | Y5: =IF(A5="","",LOWER(A5)) -> lic-260911-1127 | Z5: =IF(A5="","",IF(T5="",Settings!$B$5,T5)&IF(ISNUMBER(FIND("?",IF(T5="",Settings!$B$5,T5))),"&","?")&"utm_source="&V5&"&utm_medium="&W5&"&utm_campaign="&X5&"&utm_content="&Y5) -> https://www.alphanodus.com/contact?utm_source=linkedin&utm_medium=social&utm_campaign=product&utm_content=lic-260911-1127 | AB5: 46293 | AO5: =IF(A5="","",IF(AD5<>"",AD5,IF(AC5<>"",AC5,""))) | AP5: =IF(AO5="","",IF(AD5<>"","Reported reach","Impressions (proxy)")) | AQ5: =IF(OR(AO5="",N(S5)=0),"",AO5/S5) | AR5: =IF(A5="","",IF(COUNT(AF5:AJ5)=0,"",SUM(AF5:AJ5))) | AS5: =IF(OR(AR5="",N(AO5)=0),"",AR5/AO5) | AT5: =IF(OR(AR5="",N(AC5)=0),"",AR5/AC5) | AU5: =IF(OR(AR5="",N(S5)=0),"",AR5/S5) | AV5: =IF(OR(AJ5="",N(AC5)=0),"",AJ5/AC5) | AW5: =IF(OR(AH5="",N(AO5)=0),"",AH5/AO5) | AX5: =IF(OR(AR5="",N(AO5)=0),"",(N(AF5)*Settings!$B$6+N(AG5)*Settings!$B$7+N(AH5)*Settings!$B$8+N(AI5)*Settings!$B$9+N(AJ5)*Settings!$B$10)/AO5*1000) | AY5: =IF(AS5="","",IFERROR(AS5/AVERAGEIFS('Post Tracker'!$AS$5:$AS$1004,'Post Tracker'!$G$5:$G$1004,G5),"")) | BD5: =IF(A5="","",COUNTIFS('Demo Pipeline'!$Q$5:$Q$504,A5)) -> 0 | BE5: =IF(A5="","",COUNTIFS('Demo Pipeline'!$Q$5:$Q$504,A5,'Demo Pipeline'!$W$5:$W$504,"Attended")) -> 0 | BF5: =IF(A5="","",COUNTIFS('Demo Pipeline'!$Q$5:$Q$504,A5,'Demo Pipeline'!$X$5:$X$504,"Yes")) -> 0 | BG5: =IF(A5="","",COUNTIFS('Demo Pipeline'!$Q$5:$Q$504,A5,'Demo Pipeline'!$Y$5:$Y$504,"Closed Won")) -> 0 | BH5: =IF(A5="","",SUMIFS('Demo Pipeline'!$Z$5:$Z$504,'Demo Pipeline'!$Q$5:$Q$504,A5)) -> 0 | BI5: =IF(OR(AZ5="",N(AJ5)=0),"",AZ5/AJ5) | BJ5: =IF(OR(BB5="",N(AZ5)=0),"",BB5/AZ5) | BK5: =IF(OR(A5="",N(BB5)=0),"",BD5/BB5) | BL5: =IF(OR(A5="",N(AZ5)=0),"",BD5/AZ5) | BM5: =IF(OR(N(Q5)=0,N(BD5)=0),"",Q5/BD5) | BN5: Public-page pull 9/28. Impressions, reach, reposts & clicks aren't public - add from LinkedIn page analytics. Reaction/comment counts weren't shown publicly for this video - fill in from analytics. | BP5: =IF(OR(AR5="",N(AO5)=0),"",AR5) | BQ5: =IF(OR(AR5="",N(S5)=0),"",S5) | BR5: =IF(AND(ISNUMBER(B5),B5>=Dashboard!$C$4,B5<=Dashboard!$F$4,ISNUMBER(AU5)),AU5+ROW()/10^9,"") | BS5: =IF(AND(ISNUMBER(B5),B5>=Dashboard!$C$4,B5<=Dashboard!$F$4,A5<>""),N(BD5)+N(AU5)/100+ROW()/10^9,"") -> 5e-09
A6: =IF(OR(B6="",G6="",H6=""),"",IFERROR(INDEX(Settings!$E$5:$E$49,MATCH(G6,Settings!$D$5:$D$49,0))&INDEX(Settings!$H$5:$H$47,MATCH(H6,Settings!$G$5:$G$47,0))&"-"&TEXT(B6,"yymmdd")&"-"&IF(C6="","0000",TEXT(C6,"hhmm")),"CHECK LISTS")) -> LIC-260914-1258 | B6: 46279 | C6: 0.54027778 | D6: =IF(B6="","",TEXT(B6,"ddd")) -> Mon | E6: =IF(B6="","",B6-WEEKDAY(B6,3)) -> 46279 | F6: =IF(B6="","",TEXT(B6,"yyyy-mm")) -> 2026-09 | G6: LinkedIn | H6: Company Page | J6: Operations Tips (Scheduling, No-shows, Throughput) | L6: Scanners idle a third of the day, next slot 3 weeks out - the queue nobody owns | M6: Stat / Number | N6: Owner / CEO | O6: Comment / Engage | P6: Organic | R6: https://www.linkedin.com/posts/alphanodus_radiology-medicalimaging-imagingcenters-activity-7505309133571686400-slZz | S6: 2640 | U6: No Link | V6: =IF(A6="","",IFERROR(INDEX(Settings!$F$5:$F$49,MATCH(G6,Settings!$D$5:$D$49,0)),"")) -> linkedin | W6: =IF(A6="","",IF(OR(P6="",P6="Organic"),"social","paid_social")) -> social | X6: =IF(A6="","",IF(K6<>"",IFERROR(INDEX('Case Studies'!$C$5:$C$54,MATCH(K6,'Case Studies'!$B$5:$B$54,0))&"","case-study"),IF(J6<>"",IFERROR(INDEX(Settings!$J$5:$J$55,MATCH(J6,Settings!$I$5:$I$55,0)),"general"),"general"))) -> ops-tips | Y6: =IF(A6="","",LOWER(A6)) -> lic-260914-1258 | Z6: =IF(A6="","",IF(T6="",Settings!$B$5,T6)&IF(ISNUMBER(FIND("?",IF(T6="",Settings!$B$5,T6))),"&","?")&"utm_source="&V6&"&utm_medium="&W6&"&utm_campaign="&X6&"&utm_content="&Y6) -> https://www.alphanodus.com/contact?utm_source=linkedin&utm_medium=social&utm_campaign=ops-tips&utm_content=lic-260914-1258 | AB6: 46293 | AF6: 16 | AG6: 0 | AO6: =IF(A6="","",IF(AD6<>"",AD6,IF(AC6<>"",AC6,""))) | AP6: =IF(AO6="","",IF(AD6<>"","Reported reach","Impressions (proxy)")) | AQ6: =IF(OR(AO6="",N(S6)=0),"",AO6/S6) | AR6: =IF(A6="","",IF(COUNT(AF6:AJ6)=0,"",SUM(AF6:AJ6))) -> 16 | AS6: =IF(OR(AR6="",N(AO6)=0),"",AR6/AO6) | AT6: =IF(OR(AR6="",N(AC6)=0),"",AR6/AC6) | AU6: =IF(OR(AR6="",N(S6)=0),"",AR6/S6) -> 0.0060606061 | AV6: =IF(OR(AJ6="",N(AC6)=0),"",AJ6/AC6) | AW6: =IF(OR(AH6="",N(AO6)=0),"",AH6/AO6) | AX6: =IF(OR(AR6="",N(AO6)=0),"",(N(AF6)*Settings!$B$6+N(AG6)*Settings!$B$7+N(AH6)*Settings!$B$8+N(AI6)*Settings!$B$9+N(AJ6)*Settings!$B$10)/AO6*1000) | AY6: =IF(AS6="","",IFERROR(AS6/AVERAGEIFS('Post Tracker'!$AS$5:$AS$1004,'Post Tracker'!$G$5:$G$1004,G6),"")) | BD6: =IF(A6="","",COUNTIFS('Demo Pipeline'!$Q$5:$Q$504,A6)) -> 0 | BE6: =IF(A6="","",COUNTIFS('Demo Pipeline'!$Q$5:$Q$504,A6,'Demo Pipeline'!$W$5:$W$504,"Attended")) -> 0 | BF6: =IF(A6="","",COUNTIFS('Demo Pipeline'!$Q$5:$Q$504,A6,'Demo Pipeline'!$X$5:$X$504,"Yes")) -> 0 | BG6: =IF(A6="","",COUNTIFS('Demo Pipeline'!$Q$5:$Q$504,A6,'Demo Pipeline'!$Y$5:$Y$504,"Closed Won")) -> 0 | BH6: =IF(A6="","",SUMIFS('Demo Pipeline'!$Z$5:$Z$504,'Demo Pipeline'!$Q$5:$Q$504,A6)) -> 0 | BI6: =IF(OR(AZ6="",N(AJ6)=0),"",AZ6/AJ6) | BJ6: =IF(OR(BB6="",N(AZ6)=0),"",BB6/AZ6) | BK6: =IF(OR(A6="",N(BB6)=0),"",BD6/BB6) | BL6: =IF(OR(A6="",N(AZ6)=0),"",BD6/AZ6) | BM6: =IF(OR(N(Q6)=0,N(BD6)=0),"",Q6/BD6) | BN6: Public-page pull 9/28. Impressions, reach, reposts & clicks aren't public - add from LinkedIn page analytics. Media format not visible on the public page - set it. | BP6: =IF(OR(AR6="",N(AO6)=0),"",AR6) | BQ6: =IF(OR(AR6="",N(S6)=0),"",S6) -> 2640 | BR6: =IF(AND(ISNUMBER(B6),B6>=Dashboard!$C$4,B6<=Dashboard!$F$4,ISNUMBER(AU6)),AU6+ROW()/10^9,"") -> 0.0060606121 | BS6: =IF(AND(ISNUMBER(B6),B6>=Dashboard!$C$4,B6<=Dashboard!$F$4,A6<>""),N(BD6)+N(AU6)/100+ROW()/10^9,"") -> 6.0612061e-05
A7: =IF(OR(B7="",G7="",H7=""),"",IFERROR(INDEX(Settings!$E$5:$E$49,MATCH(G7,Settings!$D$5:$D$49,0))&INDEX(Settings!$H$5:$H$47,MATCH(H7,Settings!$G$5:$G$47,0))&"-"&TEXT(B7,"yymmdd")&"-"&IF(C7="","0000",TEXT(C7,"hhmm")),"CHECK LISTS")) -> LIC-260918-1242 | B7: 46283 | C7: 0.52916667 | D7: =IF(B7="","",TEXT(B7,"ddd")) -> Fri | E7: =IF(B7="","",B7-WEEKDAY(B7,3)) -> 46279 | F7: =IF(B7="","",TEXT(B7,"yyyy-mm")) -> 2026-09 | G7: LinkedIn | H7: Company Page | J7: Revenue Cycle & Denials | L7: An order arrives with one field missing - when does it get flagged? | M7: Story / Anecdote | N7: Revenue Cycle / Billing Lead | O7: Comment / Engage | P7: Organic | R7: https://www.linkedin.com/posts/alphanodus_radiologymanagement-revenuecyclemanagement-activity-7506754588167806979-g7vi | S7: 2640 | U7: No Link | V7: =IF(A7="","",IFERROR(INDEX(Settings!$F$5:$F$49,MATCH(G7,Settings!$D$5:$D$49,0)),"")) -> linkedin | W7: =IF(A7="","",IF(OR(P7="",P7="Organic"),"social","paid_social")) -> social | X7: =IF(A7="","",IF(K7<>"",IFERROR(INDEX('Case Studies'!$C$5:$C$54,MATCH(K7,'Case Studies'!$B$5:$B$54,0))&"","case-study"),IF(J7<>"",IFERROR(INDEX(Settings!$J$5:$J$55,MATCH(J7,Settings!$I$5:$I$55,0)),"general"),"general"))) -> rcm | Y7: =IF(A7="","",LOWER(A7)) -> lic-260918-1242 | Z7: =IF(A7="","",IF(T7="",Settings!$B$5,T7)&IF(ISNUMBER(FIND("?",IF(T7="",Settings!$B$5,T7))),"&","?")&"utm_source="&V7&"&utm_medium="&W7&"&utm_campaign="&X7&"&utm_content="&Y7) -> https://www.alphanodus.com/contact?utm_source=linkedin&utm_medium=social&utm_campaign=rcm&utm_content=lic-260918-1242 | AB7: 46293 | AF7: 5 | AG7: 1 | AO7: =IF(A7="","",IF(AD7<>"",AD7,IF(AC7<>"",AC7,""))) | AP7: =IF(AO7="","",IF(AD7<>"","Reported reach","Impressions (proxy)")) | AQ7: =IF(OR(AO7="",N(S7)=0),"",AO7/S7) | AR7: =IF(A7="","",IF(COUNT(AF7:AJ7)=0,"",SUM(AF7:AJ7))) -> 6 | AS7: =IF(OR(AR7="",N(AO7)=0),"",AR7/AO7) | AT7: =IF(OR(AR7="",N(AC7)=0),"",AR7/AC7) | AU7: =IF(OR(AR7="",N(S7)=0),"",AR7/S7) -> 0.0022727273 | AV7: =IF(OR(AJ7="",N(AC7)=0),"",AJ7/AC7) | AW7: =IF(OR(AH7="",N(AO7)=0),"",AH7/AO7) | AX7: =IF(OR(AR7="",N(AO7)=0),"",(N(AF7)*Settings!$B$6+N(AG7)*Settings!$B$7+N(AH7)*Settings!$B$8+N(AI7)*Settings!$B$9+N(AJ7)*Settings!$B$10)/AO7*1000) | AY7: =IF(AS7="","",IFERROR(AS7/AVERAGEIFS('Post Tracker'!$AS$5:$AS$1004,'Post Tracker'!$G$5:$G$1004,G7),"")) | BD7: =IF(A7="","",COUNTIFS('Demo Pipeline'!$Q$5:$Q$504,A7)) -> 0 | BE7: =IF(A7="","",COUNTIFS('Demo Pipeline'!$Q$5:$Q$504,A7,'Demo Pipeline'!$W$5:$W$504,"Attended")) -> 0 | BF7: =IF(A7="","",COUNTIFS('Demo Pipeline'!$Q$5:$Q$504,A7,'Demo Pipeline'!$X$5:$X$504,"Yes")) -> 0 | BG7: =IF(A7="","",COUNTIFS('Demo Pipeline'!$Q$5:$Q$504,A7,'Demo Pipeline'!$Y$5:$Y$504,"Closed Won")) -> 0 | BH7: =IF(A7="","",SUMIFS('Demo Pipeline'!$Z$5:$Z$504,'Demo Pipeline'!$Q$5:$Q$504,A7)) -> 0 | BI7: =IF(OR(AZ7="",N(AJ7)=0),"",AZ7/AJ7) | BJ7: =IF(OR(BB7="",N(AZ7)=0),"",BB7/AZ7) | BK7: =IF(OR(A7="",N(BB7)=0),"",BD7/BB7) | BL7: =IF(OR(A7="",N(AZ7)=0),"",BD7/AZ7) | BM7: =IF(OR(N(Q7)=0,N(BD7)=0),"",Q7/BD7) | BN7: Public-page pull 9/28. Impressions, reach, reposts & clicks aren't public - add from LinkedIn page analytics. Media format not visible on the public page - set it. | BP7: =IF(OR(AR7="",N(AO7)=0),"",AR7) | BQ7: =IF(OR(AR7="",N(S7)=0),"",S7) -> 2640 | BR7: =IF(AND(ISNUMBER(B7),B7>=Dashboard!$C$4,B7<=Dashboard!$F$4,ISNUMBER(AU7)),AU7+ROW()/10^9,"") -> 0.0022727343 | BS7: =IF(AND(ISNUMBER(B7),B7>=Dashboard!$C$4,B7<=Dashboard!$F$4,A7<>""),N(BD7)+N(AU7)/100+ROW()/10^9,"") -> 2.2734273e-05
A8: =IF(OR(B8="",G8="",H8=""),"",IFERROR(INDEX(Settings!$E$5:$E$49,MATCH(G8,Settings!$D$5:$D$49,0))&INDEX(Settings!$H$5:$H$47,MATCH(H8,Settings!$G$5:$G$47,0))&"-"&TEXT(B8,"yymmdd")&"-"&IF(C8="","0000",TEXT(C8,"hhmm")),"CHECK LISTS")) -> LIC-260923-1906 | B8: 46288 | C8: 0.79583333 | D8: =IF(B8="","",TEXT(B8,"ddd")) -> Wed | E8: =IF(B8="","",B8-WEEKDAY(B8,3)) -> 46286 | F8: =IF(B8="","",TEXT(B8,"yyyy-mm")) -> 2026-09 | G8: LinkedIn | H8: Company Page | J8: Revenue Cycle & Denials | L8: An imaging order arrives by fax: 4 manual handoffs before it's billable | M8: Story / Anecdote | N8: Revenue Cycle / Billing Lead | O8: Book a Demo | P8: Organic | R8: https://www.linkedin.com/posts/alphanodus_revenuecyclemanagement-radiology-imagingcenters-activity-7508663072018939904-A0PG | S8: 2640 | U8: First Comment | V8: =IF(A8="","",IFERROR(INDEX(Settings!$F$5:$F$49,MATCH(G8,Settings!$D$5:$D$49,0)),"")) -> linkedin | W8: =IF(A8="","",IF(OR(P8="",P8="Organic"),"social","paid_social")) -> social | X8: =IF(A8="","",IF(K8<>"",IFERROR(INDEX('Case Studies'!$C$5:$C$54,MATCH(K8,'Case Studies'!$B$5:$B$54,0))&"","case-study"),IF(J8<>"",IFERROR(INDEX(Settings!$J$5:$J$55,MATCH(J8,Settings!$I$5:$I$55,0)),"general"),"general"))) -> rcm | Y8: =IF(A8="","",LOWER(A8)) -> lic-260923-1906 | Z8: =IF(A8="","",IF(T8="",Settings!$B$5,T8)&IF(ISNUMBER(FIND("?",IF(T8="",Settings!$B$5,T8))),"&","?")&"utm_source="&V8&"&utm_medium="&W8&"&utm_campaign="&X8&"&utm_content="&Y8) -> https://www.alphanodus.com/contact?utm_source=linkedin&utm_medium=social&utm_campaign=rcm&utm_content=lic-260923-1906 | AB8: 46293 | AF8: 4 | AG8: 1 | AO8: =IF(A8="","",IF(AD8<>"",AD8,IF(AC8<>"",AC8,""))) | AP8: =IF(AO8="","",IF(AD8<>"","Reported reach","Impressions (proxy)")) | AQ8: =IF(OR(AO8="",N(S8)=0),"",AO8/S8) | AR8: =IF(A8="","",IF(COUNT(AF8:AJ8)=0,"",SUM(AF8:AJ8))) -> 5 | AS8: =IF(OR(AR8="",N(AO8)=0),"",AR8/AO8) | AT8: =IF(OR(AR8="",N(AC8)=0),"",AR8/AC8) | AU8: =IF(OR(AR8="",N(S8)=0),"",AR8/S8) -> 0.0018939394 | AV8: =IF(OR(AJ8="",N(AC8)=0),"",AJ8/AC8) | AW8: =IF(OR(AH8="",N(AO8)=0),"",AH8/AO8) | AX8: =IF(OR(AR8="",N(AO8)=0),"",(N(AF8)*Settings!$B$6+N(AG8)*Settings!$B$7+N(AH8)*Settings!$B$8+N(AI8)*Settings!$B$9+N(AJ8)*Settings!$B$10)/AO8*1000) | AY8: =IF(AS8="","",IFERROR(AS8/AVERAGEIFS('Post Tracker'!$AS$5:$AS$1004,'Post Tracker'!$G$5:$G$1004,G8),"")) | BD8: =IF(A8="","",COUNTIFS('Demo Pipeline'!$Q$5:$Q$504,A8)) -> 0 | BE8: =IF(A8="","",COUNTIFS('Demo Pipeline'!$Q$5:$Q$504,A8,'Demo Pipeline'!$W$5:$W$504,"Attended")) -> 0 | BF8: =IF(A8="","",COUNTIFS('Demo Pipeline'!$Q$5:$Q$504,A8,'Demo Pipeline'!$X$5:$X$504,"Yes")) -> 0 | BG8: =IF(A8="","",COUNTIFS('Demo Pipeline'!$Q$5:$Q$504,A8,'Demo Pipeline'!$Y$5:$Y$504,"Closed Won")) -> 0 | BH8: =IF(A8="","",SUMIFS('Demo Pipeline'!$Z$5:$Z$504,'Demo Pipeline'!$Q$5:$Q$504,A8)) -> 0 | BI8: =IF(OR(AZ8="",N(AJ8)=0),"",AZ8/AJ8) | BJ8: =IF(OR(BB8="",N(AZ8)=0),"",BB8/AZ8) | BK8: =IF(OR(A8="",N(BB8)=0),"",BD8/BB8) | BL8: =IF(OR(A8="",N(AZ8)=0),"",BD8/AZ8) | BM8: =IF(OR(N(Q8)=0,N(BD8)=0),"",Q8/BD8) | BN8: Public-page pull 9/28. Impressions, reach, reposts & clicks aren't public - add from LinkedIn page analytics. Media format not visible on the public page - set it. | BP8: =IF(OR(AR8="",N(AO8)=0),"",AR8) | BQ8: =IF(OR(AR8="",N(S8)=0),"",S8) -> 2640 | BR8: =IF(AND(ISNUMBER(B8),B8>=Dashboard!$C$4,B8<=Dashboard!$F$4,ISNUMBER(AU8)),AU8+ROW()/10^9,"") -> 0.0018939474 | BS8: =IF(AND(ISNUMBER(B8),B8>=Dashboard!$C$4,B8<=Dashboard!$F$4,A8<>""),N(BD8)+N(AU8)/100+ROW()/10^9,"") -> 1.8947394e-05
A9: =IF(OR(B9="",G9="",H9=""),"",IFERROR(INDEX(Settings!$E$5:$E$49,MATCH(G9,Settings!$D$5:$D$49,0))&INDEX(Settings!$H$5:$H$47,MATCH(H9,Settings!$G$5:$G$47,0))&"-"&TEXT(B9,"yymmdd")&"-"&IF(C9="","0000",TEXT(C9,"hhmm")),"CHECK LISTS")) -> LIC-260928-1416 | B9: 46293 | C9: 0.59444444 | D9: =IF(B9="","",TEXT(B9,"ddd")) -> Mon | E9: =IF(B9="","",B9-WEEKDAY(B9,3)) -> 46293 | F9: =IF(B9="","",TEXT(B9,"yyyy-mm")) -> 2026-09 | G9: LinkedIn | H9: Company Page | I9: Poll | J9: Industry Insight / Data | L9: Poll: How many referrals went to another center last month? | M9: Question | N9: Owner / CEO | O9: Comment / Engage | P9: Organic | R9: https://www.linkedin.com/posts/alphanodus_imagingcenters-healthcareoperations-radiology-activity-7510401945279295488-5wJH | S9: 2640 | U9: No Link | V9: =IF(A9="","",IFERROR(INDEX(Settings!$F$5:$F$49,MATCH(G9,Settings!$D$5:$D$49,0)),"")) -> linkedin | W9: =IF(A9="","",IF(OR(P9="",P9="Organic"),"social","paid_social")) -> social | X9: =IF(A9="","",IF(K9<>"",IFERROR(INDEX('Case Studies'!$C$5:$C$54,MATCH(K9,'Case Studies'!$B$5:$B$54,0))&"","case-study"),IF(J9<>"",IFERROR(INDEX(Settings!$J$5:$J$55,MATCH(J9,Settings!$I$5:$I$55,0)),"general"),"general"))) -> insight | Y9: =IF(A9="","",LOWER(A9)) -> lic-260928-1416 | Z9: =IF(A9="","",IF(T9="",Settings!$B$5,T9)&IF(ISNUMBER(FIND("?",IF(T9="",Settings!$B$5,T9))),"&","?")&"utm_source="&V9&"&utm_medium="&W9&"&utm_campaign="&X9&"&utm_content="&Y9) -> https://www.alphanodus.com/contact?utm_source=linkedin&utm_medium=social&utm_campaign=insight&utm_content=lic-260928-1416 | AB9: 46293 | AF9: 1 | AG9: 1 | AO9: =IF(A9="","",IF(AD9<>"",AD9,IF(AC9<>"",AC9,""))) | AP9: =IF(AO9="","",IF(AD9<>"","Reported reach","Impressions (proxy)")) | AQ9: =IF(OR(AO9="",N(S9)=0),"",AO9/S9) | AR9: =IF(A9="","",IF(COUNT(AF9:AJ9)=0,"",SUM(AF9:AJ9))) -> 2 | AS9: =IF(OR(AR9="",N(AO9)=0),"",AR9/AO9) | AT9: =IF(OR(AR9="",N(AC9)=0),"",AR9/AC9) | AU9: =IF(OR(AR9="",N(S9)=0),"",AR9/S9) -> 0.00075757576 | AV9: =IF(OR(AJ9="",N(AC9)=0),"",AJ9/AC9) | AW9: =IF(OR(AH9="",N(AO9)=0),"",AH9/AO9) | AX9: =IF(OR(AR9="",N(AO9)=0),"",(N(AF9)*Settings!$B$6+N(AG9)*Settings!$B$7+N(AH9)*Settings!$B$8+N(AI9)*Settings!$B$9+N(AJ9)*Settings!$B$10)/AO9*1000) | AY9: =IF(AS9="","",IFERROR(AS9/AVERAGEIFS('Post Tracker'!$AS$5:$AS$1004,'Post Tracker'!$G$5:$G$1004,G9),"")) | BD9: =IF(A9="","",COUNTIFS('Demo Pipeline'!$Q$5:$Q$504,A9)) -> 0 | BE9: =IF(A9="","",COUNTIFS('Demo Pipeline'!$Q$5:$Q$504,A9,'Demo Pipeline'!$W$5:$W$504,"Attended")) -> 0 | BF9: =IF(A9="","",COUNTIFS('Demo Pipeline'!$Q$5:$Q$504,A9,'Demo Pipeline'!$X$5:$X$504,"Yes")) -> 0 | BG9: =IF(A9="","",COUNTIFS('Demo Pipeline'!$Q$5:$Q$504,A9,'Demo Pipeline'!$Y$5:$Y$504,"Closed Won")) -> 0 | BH9: =IF(A9="","",SUMIFS('Demo Pipeline'!$Z$5:$Z$504,'Demo Pipeline'!$Q$5:$Q$504,A9)) -> 0 | BI9: =IF(OR(AZ9="",N(AJ9)=0),"",AZ9/AJ9) | BJ9: =IF(OR(BB9="",N(AZ9)=0),"",BB9/AZ9) | BK9: =IF(OR(A9="",N(BB9)=0),"",BD9/BB9) | BL9: =IF(OR(A9="",N(AZ9)=0),"",BD9/AZ9) | BM9: =IF(OR(N(Q9)=0,N(BD9)=0),"",Q9/BD9) | BN9: Public-page pull 9/28. Impressions, reach, reposts & clicks aren't public - add from LinkedIn page analytics. Only ~3 hours old when pulled - re-pull on Oct 5 before judging it. | BP9: =IF(OR(AR9="",N(AO9)=0),"",AR9) | BQ9: =IF(OR(AR9="",N(S9)=0),"",S9) -> 2640 | BR9: =IF(AND(ISNUMBER(B9),B9>=Dashboard!$C$4,B9<=Dashboard!$F$4,ISNUMBER(AU9)),AU9+ROW()/10^9,"") -> 0.00075758476 | BS9: =IF(AND(ISNUMBER(B9),B9>=Dashboard!$C$4,B9<=Dashboard!$F$4,A9<>""),N(BD9)+N(AU9)/100+ROW()/10^9,"") -> 7.5847576e-06
A10: =IF(OR(B10="",G10="",H10=""),"",IFERROR(INDEX(Settings!$E$5:$E$49,MATCH(G10,Settings!$D$5:$D$49,0))&INDEX(Settings!$H$5:$H$47,MATCH(H10,Settings!$G$5:$G$47,0))&"-"&TEXT(B10,"yymmdd")&"-"&IF(C10="","0000",TEXT(C10,"hhmm")),"CHECK LISTS")) -> IGC-260911-1147 | B10: 46276 | C10: 0.49097222 | D10: =IF(B10="","",TEXT(B10,"ddd")) -> Fri | E10: =IF(B10="","",B10-WEEKDAY(B10,3)) -> 46272 | F10: =IF(B10="","",TEXT(B10,"yyyy-mm")) -> 2026-09 | G10: Instagram | H10: Company Page | I10: Short Video / Reel | J10: Product Demo / Feature | L10: Is your imaging center still running on fax, phones and payer portals? (3-min Gravity AI explainer video) | M10: Question | N10: Owner / CEO | O10: Book a Demo | P10: Organic | R10: https://www.instagram.com/alphanodus/reel/DdJxFt3t07x/ | S10: 61 | U10: Link in Bio | V10: =IF(A10="","",IFERROR(INDEX(Settings!$F$5:$F$49,MATCH(G10,Settings!$D$5:$D$49,0)),"")) -> instagram | W10: =IF(A10="","",IF(OR(P10="",P10="Organic"),"social","paid_social")) -> social | X10: =IF(A10="","",IF(K10<>"",IFERROR(INDEX('Case Studies'!$C$5:$C$54,MATCH(K10,'Case Studies'!$B$5:$B$54,0))&"","case-study"),IF(J10<>"",IFERROR(INDEX(Settings!$J$5:$J$55,MATCH(J10,Settings!$I$5:$I$55,0)),"general"),"general"))) -> product | Y10: =IF(A10="","",LOWER(A10)) -> igc-260911-1147 | Z10: =IF(A10="","",IF(T10="",Settings!$B$5,T10)&IF(ISNUMBER(FIND("?",IF(T10="",Settings!$B$5,T10))),"&","?")&"utm_source="&V10&"&utm_medium="&W10&"&utm_campaign="&X10&"&utm_content="&Y10) -> https://www.alphanodus.com/contact?utm_source=instagram&utm_medium=social&utm_campaign=product&utm_content=igc-260911-1147 | AB10: 46293 | AF10: 7 | AG10: 0 | AO10: =IF(A10="","",IF(AD10<>"",AD10,IF(AC10<>"",AC10,""))) | AP10: =IF(AO10="","",IF(AD10<>"","Reported reach","Impressions (proxy)")) | AQ10: =IF(OR(AO10="",N(S10)=0),"",AO10/S10) | AR10: =IF(A10="","",IF(COUNT(AF10:AJ10)=0,"",SUM(AF10:AJ10))) -> 7 | AS10: =IF(OR(AR10="",N(AO10)=0),"",AR10/AO10) | AT10: =IF(OR(AR10="",N(AC10)=0),"",AR10/AC10) | AU10: =IF(OR(AR10="",N(S10)=0),"",AR10/S10) -> 0.1147541 | AV10: =IF(OR(AJ10="",N(AC10)=0),"",AJ10/AC10) | AW10: =IF(OR(AH10="",N(AO10)=0),"",AH10/AO10) | AX10: =IF(OR(AR10="",N(AO10)=0),"",(N(AF10)*Settings!$B$6+N(AG10)*Settings!$B$7+N(AH10)*Settings!$B$8+N(AI10)*Settings!$B$9+N(AJ10)*Settings!$B$10)/AO10*1000) | AY10: =IF(AS10="","",IFERROR(AS10/AVERAGEIFS('Post Tracker'!$AS$5:$AS$1004,'Post Tracker'!$G$5:$G$1004,G10),"")) | BD10: =IF(A10="","",COUNTIFS('Demo Pipeline'!$Q$5:$Q$504,A10)) -> 0 | BE10: =IF(A10="","",COUNTIFS('Demo Pipeline'!$Q$5:$Q$504,A10,'Demo Pipeline'!$W$5:$W$504,"Attended")) -> 0 | BF10: =IF(A10="","",COUNTIFS('Demo Pipeline'!$Q$5:$Q$504,A10,'Demo Pipeline'!$X$5:$X$504,"Yes")) -> 0 | BG10: =IF(A10="","",COUNTIFS('Demo Pipeline'!$Q$5:$Q$504,A10,'Demo Pipeline'!$Y$5:$Y$504,"Closed Won")) -> 0 | BH10: =IF(A10="","",SUMIFS('Demo Pipeline'!$Z$5:$Z$504,'Demo Pipeline'!$Q$5:$Q$504,A10)) -> 0 | BI10: =IF(OR(AZ10="",N(AJ10)=0),"",AZ10/AJ10) | BJ10: =IF(OR(BB10="",N(AZ10)=0),"",BB10/AZ10) | BK10: =IF(OR(A10="",N(BB10)=0),"",BD10/BB10) | BL10: =IF(OR(A10="",N(AZ10)=0),"",BD10/AZ10) | BM10: =IF(OR(N(Q10)=0,N(BD10)=0),"",Q10/BD10) | BN10: Public-page pull 9/28. Views, reach, shares & saves aren't public - add from Instagram Insights. | BP10: =IF(OR(AR10="",N(AO10)=0),"",AR10) | BQ10: =IF(OR(AR10="",N(S10)=0),"",S10) -> 61 | BR10: =IF(AND(ISNUMBER(B10),B10>=Dashboard!$C$4,B10<=Dashboard!$F$4,ISNUMBER(AU10)),AU10+ROW()/10^9,"") -> 0.11475411 | BS10: =IF(AND(ISNUMBER(B10),B10>=Dashboard!$C$4,B10<=Dashboard!$F$4,A10<>""),N(BD10)+N(AU10)/100+ROW()/10^9,"") -> 0.001147551
A11: =IF(OR(B11="",G11="",H11=""),"",IFERROR(INDEX(Settings!$E$5:$E$49,MATCH(G11,Settings!$D$5:$D$49,0))&INDEX(Settings!$H$5:$H$47,MATCH(H11,Settings!$G$5:$G$47,0))&"-"&TEXT(B11,"yymmdd")&"-"&IF(C11="","0000",TEXT(C11,"hhmm")),"CHECK LISTS")) -> IGC-260914-1301 | B11: 46279 | C11: 0.54236111 | D11: =IF(B11="","",TEXT(B11,"ddd")) -> Mon | E11: =IF(B11="","",B11-WEEKDAY(B11,3)) -> 46279 | F11: =IF(B11="","",TEXT(B11,"yyyy-mm")) -> 2026-09 | G11: Instagram | H11: Company Page | I11: Single Image | J11: Operations Tips (Scheduling, No-shows, Throughput) | L11: Scanners idle a third of the day, next slot 3 weeks out - the queue nobody owns | M11: Stat / Number | N11: Owner / CEO | O11: Comment / Engage | P11: Organic | R11: https://www.instagram.com/alphanodus/p/DdRoAPjkqqy/ | S11: 61 | U11: No Link | V11: =IF(A11="","",IFERROR(INDEX(Settings!$F$5:$F$49,MATCH(G11,Settings!$D$5:$D$49,0)),"")) -> instagram | W11: =IF(A11="","",IF(OR(P11="",P11="Organic"),"social","paid_social")) -> social | X11: =IF(A11="","",IF(K11<>"",IFERROR(INDEX('Case Studies'!$C$5:$C$54,MATCH(K11,'Case Studies'!$B$5:$B$54,0))&"","case-study"),IF(J11<>"",IFERROR(INDEX(Settings!$J$5:$J$55,MATCH(J11,Settings!$I$5:$I$55,0)),"general"),"general"))) -> ops-tips | Y11: =IF(A11="","",LOWER(A11)) -> igc-260914-1301 | Z11: =IF(A11="","",IF(T11="",Settings!$B$5,T11)&IF(ISNUMBER(FIND("?",IF(T11="",Settings!$B$5,T11))),"&","?")&"utm_source="&V11&"&utm_medium="&W11&"&utm_campaign="&X11&"&utm_content="&Y11) -> https://www.alphanodus.com/contact?utm_source=instagram&utm_medium=social&utm_campaign=ops-tips&utm_content=igc-260914-1301 | AB11: 46293 | AF11: 8 | AG11: 0 | AO11: =IF(A11="","",IF(AD11<>"",AD11,IF(AC11<>"",AC11,""))) | AP11: =IF(AO11="","",IF(AD11<>"","Reported reach","Impressions (proxy)")) | AQ11: =IF(OR(AO11="",N(S11)=0),"",AO11/S11) | AR11: =IF(A11="","",IF(COUNT(AF11:AJ11)=0,"",SUM(AF11:AJ11))) -> 8 | AS11: =IF(OR(AR11="",N(AO11)=0),"",AR11/AO11) | AT11: =IF(OR(AR11="",N(AC11)=0),"",AR11/AC11) | AU11: =IF(OR(AR11="",N(S11)=0),"",AR11/S11) -> 0.13114754 | AV11: =IF(OR(AJ11="",N(AC11)=0),"",AJ11/AC11) | AW11: =IF(OR(AH11="",N(AO11)=0),"",AH11/AO11) | AX11: =IF(OR(AR11="",N(AO11)=0),"",(N(AF11)*Settings!$B$6+N(AG11)*Settings!$B$7+N(AH11)*Settings!$B$8+N(AI11)*Settings!$B$9+N(AJ11)*Settings!$B$10)/AO11*1000) | AY11: =IF(AS11="","",IFERROR(AS11/AVERAGEIFS('Post Tracker'!$AS$5:$AS$1004,'Post Tracker'!$G$5:$G$1004,G11),"")) | BD11: =IF(A11="","",COUNTIFS('Demo Pipeline'!$Q$5:$Q$504,A11)) -> 0 | BE11: =IF(A11="","",COUNTIFS('Demo Pipeline'!$Q$5:$Q$504,A11,'Demo Pipeline'!$W$5:$W$504,"Attended")) -> 0 | BF11: =IF(A11="","",COUNTIFS('Demo Pipeline'!$Q$5:$Q$504,A11,'Demo Pipeline'!$X$5:$X$504,"Yes")) -> 0 | BG11: =IF(A11="","",COUNTIFS('Demo Pipeline'!$Q$5:$Q$504,A11,'Demo Pipeline'!$Y$5:$Y$504,"Closed Won")) -> 0 | BH11: =IF(A11="","",SUMIFS('Demo Pipeline'!$Z$5:$Z$504,'Demo Pipeline'!$Q$5:$Q$504,A11)) -> 0 | BI11: =IF(OR(AZ11="",N(AJ11)=0),"",AZ11/AJ11) | BJ11: =IF(OR(BB11="",N(AZ11)=0),"",BB11/AZ11) | BK11: =IF(OR(A11="",N(BB11)=0),"",BD11/BB11) | BL11: =IF(OR(A11="",N(AZ11)=0),"",BD11/AZ11) | BM11: =IF(OR(N(Q11)=0,N(BD11)=0),"",Q11/BD11) | BN11: Public-page pull 9/28. Views, reach, shares & saves aren't public - add from Instagram Insights. | BP11: =IF(OR(AR11="",N(AO11)=0),"",AR11) | BQ11: =IF(OR(AR11="",N(S11)=0),"",S11) -> 61 | BR11: =IF(AND(ISNUMBER(B11),B11>=Dashboard!$C$4,B11<=Dashboard!$F$4,ISNUMBER(AU11)),AU11+ROW()/10^9,"") -> 0.13114755 | BS11: =IF(AND(ISNUMBER(B11),B11>=Dashboard!$C$4,B11<=Dashboard!$F$4,A11<>""),N(BD11)+N(AU11)/100+ROW()/10^9,"") -> 0.0013114864
A12: =IF(OR(B12="",G12="",H12=""),"",IFERROR(INDEX(Settings!$E$5:$E$49,MATCH(G12,Settings!$D$5:$D$49,0))&INDEX(Settings!$H$5:$H$47,MATCH(H12,Settings!$G$5:$G$47,0))&"-"&TEXT(B12,"yymmdd")&"-"&IF(C12="","0000",TEXT(C12,"hhmm")),"CHECK LISTS")) -> IGC-260918-1418 | B12: 46283 | C12: 0.59583333 | D12: =IF(B12="","",TEXT(B12,"ddd")) -> Fri | E12: =IF(B12="","",B12-WEEKDAY(B12,3)) -> 46279 | F12: =IF(B12="","",TEXT(B12,"yyyy-mm")) -> 2026-09 | G12: Instagram | H12: Company Page | I12: Carousel / Document (PDF) | J12: Revenue Cycle & Denials | L12: An order arrives with one field missing - when does it get flagged? | M12: Story / Anecdote | N12: Revenue Cycle / Billing Lead | O12: Comment / Engage | P12: Organic | R12: https://www.instagram.com/alphanodus/p/DdcD_2JkjH0/ | S12: 61 | U12: No Link | V12: =IF(A12="","",IFERROR(INDEX(Settings!$F$5:$F$49,MATCH(G12,Settings!$D$5:$D$49,0)),"")) -> instagram | W12: =IF(A12="","",IF(OR(P12="",P12="Organic"),"social","paid_social")) -> social | X12: =IF(A12="","",IF(K12<>"",IFERROR(INDEX('Case Studies'!$C$5:$C$54,MATCH(K12,'Case Studies'!$B$5:$B$54,0))&"","case-study"),IF(J12<>"",IFERROR(INDEX(Settings!$J$5:$J$55,MATCH(J12,Settings!$I$5:$I$55,0)),"general"),"general"))) -> rcm | Y12: =IF(A12="","",LOWER(A12)) -> igc-260918-1418 | Z12: =IF(A12="","",IF(T12="",Settings!$B$5,T12)&IF(ISNUMBER(FIND("?",IF(T12="",Settings!$B$5,T12))),"&","?")&"utm_source="&V12&"&utm_medium="&W12&"&utm_campaign="&X12&"&utm_content="&Y12) -> https://www.alphanodus.com/contact?utm_source=instagram&utm_medium=social&utm_campaign=rcm&utm_content=igc-260918-1418 | AB12: 46293 | AF12: 7 | AG12: 0 | AO12: =IF(A12="","",IF(AD12<>"",AD12,IF(AC12<>"",AC12,""))) | AP12: =IF(AO12="","",IF(AD12<>"","Reported reach","Impressions (proxy)")) | AQ12: =IF(OR(AO12="",N(S12)=0),"",AO12/S12) | AR12: =IF(A12="","",IF(COUNT(AF12:AJ12)=0,"",SUM(AF12:AJ12))) -> 7 | AS12: =IF(OR(AR12="",N(AO12)=0),"",AR12/AO12) | AT12: =IF(OR(AR12="",N(AC12)=0),"",AR12/AC12) | AU12: =IF(OR(AR12="",N(S12)=0),"",AR12/S12) -> 0.1147541 | AV12: =IF(OR(AJ12="",N(AC12)=0),"",AJ12/AC12) | AW12: =IF(OR(AH12="",N(AO12)=0),"",AH12/AO12) | AX12: =IF(OR(AR12="",N(AO12)=0),"",(N(AF12)*Settings!$B$6+N(AG12)*Settings!$B$7+N(AH12)*Settings!$B$8+N(AI12)*Settings!$B$9+N(AJ12)*Settings!$B$10)/AO12*1000) | AY12: =IF(AS12="","",IFERROR(AS12/AVERAGEIFS('Post Tracker'!$AS$5:$AS$1004,'Post Tracker'!$G$5:$G$1004,G12),"")) | BD12: =IF(A12="","",COUNTIFS('Demo Pipeline'!$Q$5:$Q$504,A12)) -> 0 | BE12: =IF(A12="","",COUNTIFS('Demo Pipeline'!$Q$5:$Q$504,A12,'Demo Pipeline'!$W$5:$W$504,"Attended")) -> 0 | BF12: =IF(A12="","",COUNTIFS('Demo Pipeline'!$Q$5:$Q$504,A12,'Demo Pipeline'!$X$5:$X$504,"Yes")) -> 0 | BG12: =IF(A12="","",COUNTIFS('Demo Pipeline'!$Q$5:$Q$504,A12,'Demo Pipeline'!$Y$5:$Y$504,"Closed Won")) -> 0 | BH12: =IF(A12="","",SUMIFS('Demo Pipeline'!$Z$5:$Z$504,'Demo Pipeline'!$Q$5:$Q$504,A12)) -> 0 | BI12: =IF(OR(AZ12="",N(AJ12)=0),"",AZ12/AJ12) | BJ12: =IF(OR(BB12="",N(AZ12)=0),"",BB12/AZ12) | BK12: =IF(OR(A12="",N(BB12)=0),"",BD12/BB12) | BL12: =IF(OR(A12="",N(AZ12)=0),"",BD12/AZ12) | BM12: =IF(OR(N(Q12)=0,N(BD12)=0),"",Q12/BD12) | BN12: Public-page pull 9/28. Views, reach, shares & saves aren't public - add from Instagram Insights. | BP12: =IF(OR(AR12="",N(AO12)=0),"",AR12) | BQ12: =IF(OR(AR12="",N(S12)=0),"",S12) -> 61 | BR12: =IF(AND(ISNUMBER(B12),B12>=Dashboard!$C$4,B12<=Dashboard!$F$4,ISNUMBER(AU12)),AU12+ROW()/10^9,"") -> 0.11475411 | BS12: =IF(AND(ISNUMBER(B12),B12>=Dashboard!$C$4,B12<=Dashboard!$F$4,A12<>""),N(BD12)+N(AU12)/100+ROW()/10^9,"") -> 0.001147553
A13: =IF(OR(B13="",G13="",H13=""),"",IFERROR(INDEX(Settings!$E$5:$E$49,MATCH(G13,Settings!$D$5:$D$49,0))&INDEX(Settings!$H$5:$H$47,MATCH(H13,Settings!$G$5:$G$47,0))&"-"&TEXT(B13,"yymmdd")&"-"&IF(C13="","0000",TEXT(C13,"hhmm")),"CHECK LISTS")) -> IGC-260923-1910 | B13: 46288 | C13: 0.79861111 | D13: =IF(B13="","",TEXT(B13,"ddd")) -> Wed | E13: =IF(B13="","",B13-WEEKDAY(B13,3)) -> 46286 | F13: =IF(B13="","",TEXT(B13,"yyyy-mm")) -> 2026-09 | G13: Instagram | H13: Company Page | I13: Single Image | J13: Revenue Cycle & Denials | L13: An imaging order arrives by fax: 4 manual handoffs before it's billable | M13: Story / Anecdote | N13: Revenue Cycle / Billing Lead | O13: Book a Demo | P13: Organic | R13: https://www.instagram.com/alphanodus/p/DdpdTFWN9JR/ | S13: 61 | U13: Link in Bio | V13: =IF(A13="","",IFERROR(INDEX(Settings!$F$5:$F$49,MATCH(G13,Settings!$D$5:$D$49,0)),"")) -> instagram | W13: =IF(A13="","",IF(OR(P13="",P13="Organic"),"social","paid_social")) -> social | X13: =IF(A13="","",IF(K13<>"",IFERROR(INDEX('Case Studies'!$C$5:$C$54,MATCH(K13,'Case Studies'!$B$5:$B$54,0))&"","case-study"),IF(J13<>"",IFERROR(INDEX(Settings!$J$5:$J$55,MATCH(J13,Settings!$I$5:$I$55,0)),"general"),"general"))) -> rcm | Y13: =IF(A13="","",LOWER(A13)) -> igc-260923-1910 | Z13: =IF(A13="","",IF(T13="",Settings!$B$5,T13)&IF(ISNUMBER(FIND("?",IF(T13="",Settings!$B$5,T13))),"&","?")&"utm_source="&V13&"&utm_medium="&W13&"&utm_campaign="&X13&"&utm_content="&Y13) -> https://www.alphanodus.com/contact?utm_source=instagram&utm_medium=social&utm_campaign=rcm&utm_content=igc-260923-1910 | AB13: 46293 | AF13: 2 | AG13: 0 | AO13: =IF(A13="","",IF(AD13<>"",AD13,IF(AC13<>"",AC13,""))) | AP13: =IF(AO13="","",IF(AD13<>"","Reported reach","Impressions (proxy)")) | AQ13: =IF(OR(AO13="",N(S13)=0),"",AO13/S13) | AR13: =IF(A13="","",IF(COUNT(AF13:AJ13)=0,"",SUM(AF13:AJ13))) -> 2 | AS13: =IF(OR(AR13="",N(AO13)=0),"",AR13/AO13) | AT13: =IF(OR(AR13="",N(AC13)=0),"",AR13/AC13) | AU13: =IF(OR(AR13="",N(S13)=0),"",AR13/S13) -> 0.032786885 | AV13: =IF(OR(AJ13="",N(AC13)=0),"",AJ13/AC13) | AW13: =IF(OR(AH13="",N(AO13)=0),"",AH13/AO13) | AX13: =IF(OR(AR13="",N(AO13)=0),"",(N(AF13)*Settings!$B$6+N(AG13)*Settings!$B$7+N(AH13)*Settings!$B$8+N(AI13)*Settings!$B$9+N(AJ13)*Settings!$B$10)/AO13*1000) | AY13: =IF(AS13="","",IFERROR(AS13/AVERAGEIFS('Post Tracker'!$AS$5:$AS$1004,'Post Tracker'!$G$5:$G$1004,G13),"")) | BD13: =IF(A13="","",COUNTIFS('Demo Pipeline'!$Q$5:$Q$504,A13)) -> 0 | BE13: =IF(A13="","",COUNTIFS('Demo Pipeline'!$Q$5:$Q$504,A13,'Demo Pipeline'!$W$5:$W$504,"Attended")) -> 0 | BF13: =IF(A13="","",COUNTIFS('Demo Pipeline'!$Q$5:$Q$504,A13,'Demo Pipeline'!$X$5:$X$504,"Yes")) -> 0 | BG13: =IF(A13="","",COUNTIFS('Demo Pipeline'!$Q$5:$Q$504,A13,'Demo Pipeline'!$Y$5:$Y$504,"Closed Won")) -> 0 | BH13: =IF(A13="","",SUMIFS('Demo Pipeline'!$Z$5:$Z$504,'Demo Pipeline'!$Q$5:$Q$504,A13)) -> 0 | BI13: =IF(OR(AZ13="",N(AJ13)=0),"",AZ13/AJ13) | BJ13: =IF(OR(BB13="",N(AZ13)=0),"",BB13/AZ13) | BK13: =IF(OR(A13="",N(BB13)=0),"",BD13/BB13) | BL13: =IF(OR(A13="",N(AZ13)=0),"",BD13/AZ13) | BM13: =IF(OR(N(Q13)=0,N(BD13)=0),"",Q13/BD13) | BN13: Public-page pull 9/28. Views, reach, shares & saves aren't public - add from Instagram Insights. | BP13: =IF(OR(AR13="",N(AO13)=0),"",AR13) | BQ13: =IF(OR(AR13="",N(S13)=0),"",S13) -> 61 | BR13: =IF(AND(ISNUMBER(B13),B13>=Dashboard!$C$4,B13<=Dashboard!$F$4,ISNUMBER(AU13)),AU13+ROW()/10^9,"") -> 0.032786898 | BS13: =IF(AND(ISNUMBER(B13),B13>=Dashboard!$C$4,B13<=Dashboard!$F$4,A13<>""),N(BD13)+N(AU13)/100+ROW()/10^9,"") -> 0.00032788185
A14: =IF(OR(B14="",G14="",H14=""),"",IFERROR(INDEX(Settings!$E$5:$E$49,MATCH(G14,Settings!$D$5:$D$49,0))&INDEX(Settings!$H$5:$H$47,MATCH(H14,Settings!$G$5:$G$47,0))&"-"&TEXT(B14,"yymmdd")&"-"&IF(C14="","0000",TEXT(C14,"hhmm")),"CHECK LISTS")) -> XC-260911-1129 | B14: 46276 | C14: 0.47847222 | D14: =IF(B14="","",TEXT(B14,"ddd")) -> Fri | E14: =IF(B14="","",B14-WEEKDAY(B14,3)) -> 46272 | F14: =IF(B14="","",TEXT(B14,"yyyy-mm")) -> 2026-09 | G14: X | H14: Company Page | I14: Long Video | J14: Product Demo / Feature | L14: Is your imaging center still running on fax, phones and payer portals? (3-min Gravity AI explainer video) | M14: Question | N14: Owner / CEO | O14: Book a Demo | P14: Organic | R14: https://x.com/AlphaNodus/status/2098433794022006872 | S14: 46 | U14: In Post Body | V14: =IF(A14="","",IFERROR(INDEX(Settings!$F$5:$F$49,MATCH(G14,Settings!$D$5:$D$49,0)),"")) -> twitter | W14: =IF(A14="","",IF(OR(P14="",P14="Organic"),"social","paid_social")) -> social | X14: =IF(A14="","",IF(K14<>"",IFERROR(INDEX('Case Studies'!$C$5:$C$54,MATCH(K14,'Case Studies'!$B$5:$B$54,0))&"","case-study"),IF(J14<>"",IFERROR(INDEX(Settings!$J$5:$J$55,MATCH(J14,Settings!$I$5:$I$55,0)),"general"),"general"))) -> product | Y14: =IF(A14="","",LOWER(A14)) -> xc-260911-1129 | Z14: =IF(A14="","",IF(T14="",Settings!$B$5,T14)&IF(ISNUMBER(FIND("?",IF(T14="",Settings!$B$5,T14))),"&","?")&"utm_source="&V14&"&utm_medium="&W14&"&utm_campaign="&X14&"&utm_content="&Y14) -> https://www.alphanodus.com/contact?utm_source=twitter&utm_medium=social&utm_campaign=product&utm_content=xc-260911-1129 | AB14: 46293 | AC14: 27 | AF14: 0 | AG14: 0 | AH14: 0 | AO14: =IF(A14="","",IF(AD14<>"",AD14,IF(AC14<>"",AC14,""))) -> 27 | AP14: =IF(AO14="","",IF(AD14<>"","Reported reach","Impressions (proxy)")) -> Impressions (proxy) | AQ14: =IF(OR(AO14="",N(S14)=0),"",AO14/S14) -> 0.58695652 | AR14: =IF(A14="","",IF(COUNT(AF14:AJ14)=0,"",SUM(AF14:AJ14))) -> 0 | AS14: =IF(OR(AR14="",N(AO14)=0),"",AR14/AO14) -> 0 | AT14: =IF(OR(AR14="",N(AC14)=0),"",AR14/AC14) -> 0 | AU14: =IF(OR(AR14="",N(S14)=0),"",AR14/S14) -> 0 | AV14: =IF(OR(AJ14="",N(AC14)=0),"",AJ14/AC14) | AW14: =IF(OR(AH14="",N(AO14)=0),"",AH14/AO14) -> 0 | AX14: =IF(OR(AR14="",N(AO14)=0),"",(N(AF14)*Settings!$B$6+N(AG14)*Settings!$B$7+N(AH14)*Settings!$B$8+N(AI14)*Settings!$B$9+N(AJ14)*Settings!$B$10)/AO14*1000) -> 0 | AY14: =IF(AS14="","",IFERROR(AS14/AVERAGEIFS('Post Tracker'!$AS$5:$AS$1004,'Post Tracker'!$G$5:$G$1004,G14),"")) -> 0 | BD14: =IF(A14="","",COUNTIFS('Demo Pipeline'!$Q$5:$Q$504,A14)) -> 0 | BE14: =IF(A14="","",COUNTIFS('Demo Pipeline'!$Q$5:$Q$504,A14,'Demo Pipeline'!$W$5:$W$504,"Attended")) -> 0 | BF14: =IF(A14="","",COUNTIFS('Demo Pipeline'!$Q$5:$Q$504,A14,'Demo Pipeline'!$X$5:$X$504,"Yes")) -> 0 | BG14: =IF(A14="","",COUNTIFS('Demo Pipeline'!$Q$5:$Q$504,A14,'Demo Pipeline'!$Y$5:$Y$504,"Closed Won")) -> 0 | BH14: =IF(A14="","",SUMIFS('Demo Pipeline'!$Z$5:$Z$504,'Demo Pipeline'!$Q$5:$Q$504,A14)) -> 0 | BI14: =IF(OR(AZ14="",N(AJ14)=0),"",AZ14/AJ14) | BJ14: =IF(OR(BB14="",N(AZ14)=0),"",BB14/AZ14) | BK14: =IF(OR(A14="",N(BB14)=0),"",BD14/BB14) | BL14: =IF(OR(A14="",N(AZ14)=0),"",BD14/AZ14) | BM14: =IF(OR(N(Q14)=0,N(BD14)=0),"",Q14/BD14) | BN14: Public-profile pull 9/28 (views shown as impressions; likes/reposts not shown = 0). Confirm in X post analytics. | BP14: =IF(OR(AR14="",N(AO14)=0),"",AR14) -> 0 | BQ14: =IF(OR(AR14="",N(S14)=0),"",S14) -> 46 | BR14: =IF(AND(ISNUMBER(B14),B14>=Dashboard!$C$4,B14<=Dashboard!$F$4,ISNUMBER(AU14)),AU14+ROW()/10^9,"") -> 1.4e-08 | BS14: =IF(AND(ISNUMBER(B14),B14>=Dashboard!$C$4,B14<=Dashboard!$F$4,A14<>""),N(BD14)+N(AU14)/100+ROW()/10^9,"") -> 1.4e-08
A15: =IF(OR(B15="",G15="",H15=""),"",IFERROR(INDEX(Settings!$E$5:$E$49,MATCH(G15,Settings!$D$5:$D$49,0))&INDEX(Settings!$H$5:$H$47,MATCH(H15,Settings!$G$5:$G$47,0))&"-"&TEXT(B15,"yymmdd")&"-"&IF(C15="","0000",TEXT(C15,"hhmm")),"CHECK LISTS")) -> XC-260914-1307 | B15: 46279 | C15: 0.54652778 | D15: =IF(B15="","",TEXT(B15,"ddd")) -> Mon | E15: =IF(B15="","",B15-WEEKDAY(B15,3)) -> 46279 | F15: =IF(B15="","",TEXT(B15,"yyyy-mm")) -> 2026-09 | G15: X | H15: Company Page | I15: Single Image | J15: Operations Tips (Scheduling, No-shows, Throughput) | L15: Scanners idle a third of the day, next slot 3 weeks out - the queue nobody owns | M15: Stat / Number | N15: Owner / CEO | O15: Comment / Engage | P15: Organic | R15: https://x.com/AlphaNodus/status/2099545479755583973 | S15: 46 | U15: No Link | V15: =IF(A15="","",IFERROR(INDEX(Settings!$F$5:$F$49,MATCH(G15,Settings!$D$5:$D$49,0)),"")) -> twitter | W15: =IF(A15="","",IF(OR(P15="",P15="Organic"),"social","paid_social")) -> social | X15: =IF(A15="","",IF(K15<>"",IFERROR(INDEX('Case Studies'!$C$5:$C$54,MATCH(K15,'Case Studies'!$B$5:$B$54,0))&"","case-study"),IF(J15<>"",IFERROR(INDEX(Settings!$J$5:$J$55,MATCH(J15,Settings!$I$5:$I$55,0)),"general"),"general"))) -> ops-tips | Y15: =IF(A15="","",LOWER(A15)) -> xc-260914-1307 | Z15: =IF(A15="","",IF(T15="",Settings!$B$5,T15)&IF(ISNUMBER(FIND("?",IF(T15="",Settings!$B$5,T15))),"&","?")&"utm_source="&V15&"&utm_medium="&W15&"&utm_campaign="&X15&"&utm_content="&Y15) -> https://www.alphanodus.com/contact?utm_source=twitter&utm_medium=social&utm_campaign=ops-tips&utm_content=xc-260914-1307 | AB15: 46293 | AC15: 16 | AF15: 0 | AG15: 0 | AH15: 0 | AO15: =IF(A15="","",IF(AD15<>"",AD15,IF(AC15<>"",AC15,""))) -> 16 | AP15: =IF(AO15="","",IF(AD15<>"","Reported reach","Impressions (proxy)")) -> Impressions (proxy) | AQ15: =IF(OR(AO15="",N(S15)=0),"",AO15/S15) -> 0.34782609 | AR15: =IF(A15="","",IF(COUNT(AF15:AJ15)=0,"",SUM(AF15:AJ15))) -> 0 | AS15: =IF(OR(AR15="",N(AO15)=0),"",AR15/AO15) -> 0 | AT15: =IF(OR(AR15="",N(AC15)=0),"",AR15/AC15) -> 0 | AU15: =IF(OR(AR15="",N(S15)=0),"",AR15/S15) -> 0 | AV15: =IF(OR(AJ15="",N(AC15)=0),"",AJ15/AC15) | AW15: =IF(OR(AH15="",N(AO15)=0),"",AH15/AO15) -> 0 | AX15: =IF(OR(AR15="",N(AO15)=0),"",(N(AF15)*Settings!$B$6+N(AG15)*Settings!$B$7+N(AH15)*Settings!$B$8+N(AI15)*Settings!$B$9+N(AJ15)*Settings!$B$10)/AO15*1000) -> 0 | AY15: =IF(AS15="","",IFERROR(AS15/AVERAGEIFS('Post Tracker'!$AS$5:$AS$1004,'Post Tracker'!$G$5:$G$1004,G15),"")) -> 0 | BD15: =IF(A15="","",COUNTIFS('Demo Pipeline'!$Q$5:$Q$504,A15)) -> 0 | BE15: =IF(A15="","",COUNTIFS('Demo Pipeline'!$Q$5:$Q$504,A15,'Demo Pipeline'!$W$5:$W$504,"Attended")) -> 0 | BF15: =IF(A15="","",COUNTIFS('Demo Pipeline'!$Q$5:$Q$504,A15,'Demo Pipeline'!$X$5:$X$504,"Yes")) -> 0 | BG15: =IF(A15="","",COUNTIFS('Demo Pipeline'!$Q$5:$Q$504,A15,'Demo Pipeline'!$Y$5:$Y$504,"Closed Won")) -> 0 | BH15: =IF(A15="","",SUMIFS('Demo Pipeline'!$Z$5:$Z$504,'Demo Pipeline'!$Q$5:$Q$504,A15)) -> 0 | BI15: =IF(OR(AZ15="",N(AJ15)=0),"",AZ15/AJ15) | BJ15: =IF(OR(BB15="",N(AZ15)=0),"",BB15/AZ15) | BK15: =IF(OR(A15="",N(BB15)=0),"",BD15/BB15) | BL15: =IF(OR(A15="",N(AZ15)=0),"",BD15/AZ15) | BM15: =IF(OR(N(Q15)=0,N(BD15)=0),"",Q15/BD15) | BN15: Public-profile pull 9/28 (views shown as impressions; likes/reposts not shown = 0). Confirm in X post analytics. | BP15: =IF(OR(AR15="",N(AO15)=0),"",AR15) -> 0 | BQ15: =IF(OR(AR15="",N(S15)=0),"",S15) -> 46 | BR15: =IF(AND(ISNUMBER(B15),B15>=Dashboard!$C$4,B15<=Dashboard!$F$4,ISNUMBER(AU15)),AU15+ROW()/10^9,"") -> 1.5e-08 | BS15: =IF(AND(ISNUMBER(B15),B15>=Dashboard!$C$4,B15<=Dashboard!$F$4,A15<>""),N(BD15)+N(AU15)/100+ROW()/10^9,"") -> 1.5e-08
A16: =IF(OR(B16="",G16="",H16=""),"",IFERROR(INDEX(Settings!$E$5:$E$49,MATCH(G16,Settings!$D$5:$D$49,0))&INDEX(Settings!$H$5:$H$47,MATCH(H16,Settings!$G$5:$G$47,0))&"-"&TEXT(B16,"yymmdd")&"-"&IF(C16="","0000",TEXT(C16,"hhmm")),"CHECK LISTS")) -> XC-260918-1435 | B16: 46283 | C16: 0.60763889 | D16: =IF(B16="","",TEXT(B16,"ddd")) -> Fri | E16: =IF(B16="","",B16-WEEKDAY(B16,3)) -> 46279 | F16: =IF(B16="","",TEXT(B16,"yyyy-mm")) -> 2026-09 | G16: X | H16: Company Page | I16: Single Image | J16: Revenue Cycle & Denials | L16: An order arrives with one field missing - when does it get flagged? | M16: Story / Anecdote | N16: Revenue Cycle / Billing Lead | O16: Comment / Engage | P16: Organic | R16: https://x.com/AlphaNodus/status/2101017252221128863 | S16: 46 | U16: No Link | V16: =IF(A16="","",IFERROR(INDEX(Settings!$F$5:$F$49,MATCH(G16,Settings!$D$5:$D$49,0)),"")) -> twitter | W16: =IF(A16="","",IF(OR(P16="",P16="Organic"),"social","paid_social")) -> social | X16: =IF(A16="","",IF(K16<>"",IFERROR(INDEX('Case Studies'!$C$5:$C$54,MATCH(K16,'Case Studies'!$B$5:$B$54,0))&"","case-study"),IF(J16<>"",IFERROR(INDEX(Settings!$J$5:$J$55,MATCH(J16,Settings!$I$5:$I$55,0)),"general"),"general"))) -> rcm | Y16: =IF(A16="","",LOWER(A16)) -> xc-260918-1435 | Z16: =IF(A16="","",IF(T16="",Settings!$B$5,T16)&IF(ISNUMBER(FIND("?",IF(T16="",Settings!$B$5,T16))),"&","?")&"utm_source="&V16&"&utm_medium="&W16&"&utm_campaign="&X16&"&utm_content="&Y16) -> https://www.alphanodus.com/contact?utm_source=twitter&utm_medium=social&utm_campaign=rcm&utm_content=xc-260918-1435 | AB16: 46293 | AC16: 26 | AF16: 0 | AG16: 1 | AH16: 0 | AO16: =IF(A16="","",IF(AD16<>"",AD16,IF(AC16<>"",AC16,""))) -> 26 | AP16: =IF(AO16="","",IF(AD16<>"","Reported reach","Impressions (proxy)")) -> Impressions (proxy) | AQ16: =IF(OR(AO16="",N(S16)=0),"",AO16/S16) -> 0.56521739 | AR16: =IF(A16="","",IF(COUNT(AF16:AJ16)=0,"",SUM(AF16:AJ16))) -> 1 | AS16: =IF(OR(AR16="",N(AO16)=0),"",AR16/AO16) -> 0.038461538 | AT16: =IF(OR(AR16="",N(AC16)=0),"",AR16/AC16) -> 0.038461538 | AU16: =IF(OR(AR16="",N(S16)=0),"",AR16/S16) -> 0.02173913 | AV16: =IF(OR(AJ16="",N(AC16)=0),"",AJ16/AC16) | AW16: =IF(OR(AH16="",N(AO16)=0),"",AH16/AO16) -> 0 | AX16: =IF(OR(AR16="",N(AO16)=0),"",(N(AF16)*Settings!$B$6+N(AG16)*Settings!$B$7+N(AH16)*Settings!$B$8+N(AI16)*Settings!$B$9+N(AJ16)*Settings!$B$10)/AO16*1000) -> 115.38462 | AY16: =IF(AS16="","",IFERROR(AS16/AVERAGEIFS('Post Tracker'!$AS$5:$AS$1004,'Post Tracker'!$G$5:$G$1004,G16),"")) -> 1.3333333 | BD16: =IF(A16="","",COUNTIFS('Demo Pipeline'!$Q$5:$Q$504,A16)) -> 0 | BE16: =IF(A16="","",COUNTIFS('Demo Pipeline'!$Q$5:$Q$504,A16,'Demo Pipeline'!$W$5:$W$504,"Attended")) -> 0 | BF16: =IF(A16="","",COUNTIFS('Demo Pipeline'!$Q$5:$Q$504,A16,'Demo Pipeline'!$X$5:$X$504,"Yes")) -> 0 | BG16: =IF(A16="","",COUNTIFS('Demo Pipeline'!$Q$5:$Q$504,A16,'Demo Pipeline'!$Y$5:$Y$504,"Closed Won")) -> 0 | BH16: =IF(A16="","",SUMIFS('Demo Pipeline'!$Z$5:$Z$504,'Demo Pipeline'!$Q$5:$Q$504,A16)) -> 0 | BI16: =IF(OR(AZ16="",N(AJ16)=0),"",AZ16/AJ16) | BJ16: =IF(OR(BB16="",N(AZ16)=0),"",BB16/AZ16) | BK16: =IF(OR(A16="",N(BB16)=0),"",BD16/BB16) | BL16: =IF(OR(A16="",N(AZ16)=0),"",BD16/AZ16) | BM16: =IF(OR(N(Q16)=0,N(BD16)=0),"",Q16/BD16) | BN16: Public-profile pull 9/28 (views shown as impressions; likes/reposts not shown = 0). Confirm in X post analytics. | BP16: =IF(OR(AR16="",N(AO16)=0),"",AR16) -> 1 | BQ16: =IF(OR(AR16="",N(S16)=0),"",S16) -> 46 | BR16: =IF(AND(ISNUMBER(B16),B16>=Dashboard!$C$4,B16<=Dashboard!$F$4,ISNUMBER(AU16)),AU16+ROW()/10^9,"") -> 0.021739146 | BS16: =IF(AND(ISNUMBER(B16),B16>=Dashboard!$C$4,B16<=Dashboard!$F$4,A16<>""),N(BD16)+N(AU16)/100+ROW()/10^9,"") -> 0.0002174073
A17: =IF(OR(B17="",G17="",H17=""),"",IFERROR(INDEX(Settings!$E$5:$E$49,MATCH(G17,Settings!$D$5:$D$49,0))&INDEX(Settings!$H$5:$H$47,MATCH(H17,Settings!$G$5:$G$47,0))&"-"&TEXT(B17,"yymmdd")&"-"&IF(C17="","0000",TEXT(C17,"hhmm")),"CHECK LISTS")) -> XC-260923-2019 | B17: 46288 | C17: 0.84652778 | D17: =IF(B17="","",TEXT(B17,"ddd")) -> Wed | E17: =IF(B17="","",B17-WEEKDAY(B17,3)) -> 46286 | F17: =IF(B17="","",TEXT(B17,"yyyy-mm")) -> 2026-09 | G17: X | H17: Company Page | I17: Single Image | J17: Revenue Cycle & Denials | L17: An imaging order arrives by fax: 4 manual handoffs before it's billable | M17: Story / Anecdote | N17: Revenue Cycle / Billing Lead | O17: Book a Demo | P17: Organic | R17: https://x.com/AlphaNodus/status/2102915695722045558 | S17: 46 | U17: First Comment | V17: =IF(A17="","",IFERROR(INDEX(Settings!$F$5:$F$49,MATCH(G17,Settings!$D$5:$D$49,0)),"")) -> twitter | W17: =IF(A17="","",IF(OR(P17="",P17="Organic"),"social","paid_social")) -> social | X17: =IF(A17="","",IF(K17<>"",IFERROR(INDEX('Case Studies'!$C$5:$C$54,MATCH(K17,'Case Studies'!$B$5:$B$54,0))&"","case-study"),IF(J17<>"",IFERROR(INDEX(Settings!$J$5:$J$55,MATCH(J17,Settings!$I$5:$I$55,0)),"general"),"general"))) -> rcm | Y17: =IF(A17="","",LOWER(A17)) -> xc-260923-2019 | Z17: =IF(A17="","",IF(T17="",Settings!$B$5,T17)&IF(ISNUMBER(FIND("?",IF(T17="",Settings!$B$5,T17))),"&","?")&"utm_source="&V17&"&utm_medium="&W17&"&utm_campaign="&X17&"&utm_content="&Y17) -> https://www.alphanodus.com/contact?utm_source=twitter&utm_medium=social&utm_campaign=rcm&utm_content=xc-260923-2019 | AB17: 46293 | AC17: 13 | AF17: 0 | AG17: 1 | AH17: 0 | AO17: =IF(A17="","",IF(AD17<>"",AD17,IF(AC17<>"",AC17,""))) -> 13 | AP17: =IF(AO17="","",IF(AD17<>"","Reported reach","Impressions (proxy)")) -> Impressions (proxy) | AQ17: =IF(OR(AO17="",N(S17)=0),"",AO17/S17) -> 0.2826087 | AR17: =IF(A17="","",IF(COUNT(AF17:AJ17)=0,"",SUM(AF17:AJ17))) -> 1 | AS17: =IF(OR(AR17="",N(AO17)=0),"",AR17/AO17) -> 0.076923077 | AT17: =IF(OR(AR17="",N(AC17)=0),"",AR17/AC17) -> 0.076923077 | AU17: =IF(OR(AR17="",N(S17)=0),"",AR17/S17) -> 0.02173913 | AV17: =IF(OR(AJ17="",N(AC17)=0),"",AJ17/AC17) | AW17: =IF(OR(AH17="",N(AO17)=0),"",AH17/AO17) -> 0 | AX17: =IF(OR(AR17="",N(AO17)=0),"",(N(AF17)*Settings!$B$6+N(AG17)*Settings!$B$7+N(AH17)*Settings!$B$8+N(AI17)*Settings!$B$9+N(AJ17)*Settings!$B$10)/AO17*1000) -> 230.76923 | AY17: =IF(AS17="","",IFERROR(AS17/AVERAGEIFS('Post Tracker'!$AS$5:$AS$1004,'Post Tracker'!$G$5:$G$1004,G17),"")) -> 2.6666667 | BD17: =IF(A17="","",COUNTIFS('Demo Pipeline'!$Q$5:$Q$504,A17)) -> 0 | BE17: =IF(A17="","",COUNTIFS('Demo Pipeline'!$Q$5:$Q$504,A17,'Demo Pipeline'!$W$5:$W$504,"Attended")) -> 0 | BF17: =IF(A17="","",COUNTIFS('Demo Pipeline'!$Q$5:$Q$504,A17,'Demo Pipeline'!$X$5:$X$504,"Yes")) -> 0 | BG17: =IF(A17="","",COUNTIFS('Demo Pipeline'!$Q$5:$Q$504,A17,'Demo Pipeline'!$Y$5:$Y$504,"Closed Won")) -> 0 | BH17: =IF(A17="","",SUMIFS('Demo Pipeline'!$Z$5:$Z$504,'Demo Pipeline'!$Q$5:$Q$504,A17)) -> 0 | BI17: =IF(OR(AZ17="",N(AJ17)=0),"",AZ17/AJ17) | BJ17: =IF(OR(BB17="",N(AZ17)=0),"",BB17/AZ17) | BK17: =IF(OR(A17="",N(BB17)=0),"",BD17/BB17) | BL17: =IF(OR(A17="",N(AZ17)=0),"",BD17/AZ17) | BM17: =IF(OR(N(Q17)=0,N(BD17)=0),"",Q17/BD17) | BN17: Public-profile pull 9/28 (views shown as impressions; likes/reposts not shown = 0). Confirm in X post analytics. | BP17: =IF(OR(AR17="",N(AO17)=0),"",AR17) -> 1 | BQ17: =IF(OR(AR17="",N(S17)=0),"",S17) -> 46 | BR17: =IF(AND(ISNUMBER(B17),B17>=Dashboard!$C$4,B17<=Dashboard!$F$4,ISNUMBER(AU17)),AU17+ROW()/10^9,"") -> 0.021739147 | BS17: =IF(AND(ISNUMBER(B17),B17>=Dashboard!$C$4,B17<=Dashboard!$F$4,A17<>""),N(BD17)+N(AU17)/100+ROW()/10^9,"") -> 0.0002174083
A18: =IF(OR(B18="",G18="",H18=""),"",IFERROR(INDEX(Settings!$E$5:$E$49,MATCH(G18,Settings!$D$5:$D$49,0))&INDEX(Settings!$H$5:$H$47,MATCH(H18,Settings!$G$5:$G$47,0))&"-"&TEXT(B18,"yymmdd")&"-"&IF(C18="","0000",TEXT(C18,"hhmm")),"CHECK LISTS")) | D18: =IF(B18="","",TEXT(B18,"ddd")) | E18: =IF(B18="","",B18-WEEKDAY(B18,3)) | F18: =IF(B18="","",TEXT(B18,"yyyy-mm")) | V18: =IF(A18="","",IFERROR(INDEX(Settings!$F$5:$F$49,MATCH(G18,Settings!$D$5:$D$49,0)),"")) | W18: =IF(A18="","",IF(OR(P18="",P18="Organic"),"social","paid_social")) | X18: =IF(A18="","",IF(K18<>"",IFERROR(INDEX('Case Studies'!$C$5:$C$54,MATCH(K18,'Case Studies'!$B$5:$B$54,0))&"","case-study"),IF(J18<>"",IFERROR(INDEX(Settings!$J$5:$J$55,MATCH(J18,Settings!$I$5:$I$55,0)),"general"),"general"))) | Y18: =IF(A18="","",LOWER(A18)) | Z18: =IF(A18="","",IF(T18="",Settings!$B$5,T18)&IF(ISNUMBER(FIND("?",IF(T18="",Settings!$B$5,T18))),"&","?")&"utm_source="&V18&"&utm_medium="&W18&"&utm_campaign="&X18&"&utm_content="&Y18) | AO18: =IF(A18="","",IF(AD18<>"",AD18,IF(AC18<>"",AC18,""))) | AP18: =IF(AO18="","",IF(AD18<>"","Reported reach","Impressions (proxy)")) | AQ18: =IF(OR(AO18="",N(S18)=0),"",AO18/S18) | AR18: =IF(A18="","",IF(COUNT(AF18:AJ18)=0,"",SUM(AF18:AJ18))) | AS18: =IF(OR(AR18="",N(AO18)=0),"",AR18/AO18) | AT18: =IF(OR(AR18="",N(AC18)=0),"",AR18/AC18) | AU18: =IF(OR(AR18="",N(S18)=0),"",AR18/S18) | AV18: =IF(OR(AJ18="",N(AC18)=0),"",AJ18/AC18) | AW18: =IF(OR(AH18="",N(AO18)=0),"",AH18/AO18) | AX18: =IF(OR(AR18="",N(AO18)=0),"",(N(AF18)*Settings!$B$6+N(AG18)*Settings!$B$7+N(AH18)*Settings!$B$8+N(AI18)*Settings!$B$9+N(AJ18)*Settings!$B$10)/AO18*1000) | AY18: =IF(AS18="","",IFERROR(AS18/AVERAGEIFS('Post Tracker'!$AS$5:$AS$1004,'Post Tracker'!$G$5:$G$1004,G18),"")) | BD18: =IF(A18="","",COUNTIFS('Demo Pipeline'!$Q$5:$Q$504,A18)) | BE18: =IF(A18="","",COUNTIFS('Demo Pipeline'!$Q$5:$Q$504,A18,'Demo Pipeline'!$W$5:$W$504,"Attended")) | BF18: =IF(A18="","",COUNTIFS('Demo Pipeline'!$Q$5:$Q$504,A18,'Demo Pipeline'!$X$5:$X$504,"Yes")) | BG18: =IF(A18="","",COUNTIFS('Demo Pipeline'!$Q$5:$Q$504,A18,'Demo Pipeline'!$Y$5:$Y$504,"Closed Won")) | BH18: =IF(A18="","",SUMIFS('Demo Pipeline'!$Z$5:$Z$504,'Demo Pipeline'!$Q$5:$Q$504,A18)) | BI18: =IF(OR(AZ18="",N(AJ18)=0),"",AZ18/AJ18) | BJ18: =IF(OR(BB18="",N(AZ18)=0),"",BB18/AZ18) | BK18: =IF(OR(A18="",N(BB18)=0),"",BD18/BB18) | BL18: =IF(OR(A18="",N(AZ18)=0),"",BD18/AZ18) | BM18: =IF(OR(N(Q18)=0,N(BD18)=0),"",Q18/BD18) | BP18: =IF(OR(AR18="",N(AO18)=0),"",AR18) | BQ18: =IF(OR(AR18="",N(S18)=0),"",S18) | BR18: =IF(AND(ISNUMBER(B18),B18>=Dashboard!$C$4,B18<=Dashboard!$F$4,ISNUMBER(AU18)),AU18+ROW()/10^9,"") | BS18: =IF(AND(ISNUMBER(B18),B18>=Dashboard!$C$4,B18<=Dashboard!$F$4,A18<>""),N(BD18)+N(AU18)/100+ROW()/10^9,"")
A19: =IF(OR(B19="",G19="",H19=""),"",IFERROR(INDEX(Settings!$E$5:$E$49,MATCH(G19,Settings!$D$5:$D$49,0))&INDEX(Settings!$H$5:$H$47,MATCH(H19,Settings!$G$5:$G$47,0))&"-"&TEXT(B19,"yymmdd")&"-"&IF(C19="","0000",TEXT(C19,"hhmm")),"CHECK LISTS")) | D19: =IF(B19="","",TEXT(B19,"ddd")) | E19: =IF(B19="","",B19-WEEKDAY(B19,3)) | F19: =IF(B19="","",TEXT(B19,"yyyy-mm")) | V19: =IF(A19="","",IFERROR(INDEX(Settings!$F$5:$F$49,MATCH(G19,Settings!$D$5:$D$49,0)),"")) | W19: =IF(A19="","",IF(OR(P19="",P19="Organic"),"social","paid_social")) | X19: =IF(A19="","",IF(K19<>"",IFERROR(INDEX('Case Studies'!$C$5:$C$54,MATCH(K19,'Case Studies'!$B$5:$B$54,0))&"","case-study"),IF(J19<>"",IFERROR(INDEX(Settings!$J$5:$J$55,MATCH(J19,Settings!$I$5:$I$55,0)),"general"),"general"))) | Y19: =IF(A19="","",LOWER(A19)) | Z19: =IF(A19="","",IF(T19="",Settings!$B$5,T19)&IF(ISNUMBER(FIND("?",IF(T19="",Settings!$B$5,T19))),"&","?")&"utm_source="&V19&"&utm_medium="&W19&"&utm_campaign="&X19&"&utm_content="&Y19) | AO19: =IF(A19="","",IF(AD19<>"",AD19,IF(AC19<>"",AC19,""))) | AP19: =IF(AO19="","",IF(AD19<>"","Reported reach","Impressions (proxy)")) | AQ19: =IF(OR(AO19="",N(S19)=0),"",AO19/S19) | AR19: =IF(A19="","",IF(COUNT(AF19:AJ19)=0,"",SUM(AF19:AJ19))) | AS19: =IF(OR(AR19="",N(AO19)=0),"",AR19/AO19) | AT19: =IF(OR(AR19="",N(AC19)=0),"",AR19/AC19) | AU19: =IF(OR(AR19="",N(S19)=0),"",AR19/S19) | AV19: =IF(OR(AJ19="",N(AC19)=0),"",AJ19/AC19) | AW19: =IF(OR(AH19="",N(AO19)=0),"",AH19/AO19) | AX19: =IF(OR(AR19="",N(AO19)=0),"",(N(AF19)*Settings!$B$6+N(AG19)*Settings!$B$7+N(AH19)*Settings!$B$8+N(AI19)*Settings!$B$9+N(AJ19)*Settings!$B$10)/AO19*1000) | AY19: =IF(AS19="","",IFERROR(AS19/AVERAGEIFS('Post Tracker'!$AS$5:$AS$1004,'Post Tracker'!$G$5:$G$1004,G19),"")) | BD19: =IF(A19="","",COUNTIFS('Demo Pipeline'!$Q$5:$Q$504,A19)) | BE19: =IF(A19="","",COUNTIFS('Demo Pipeline'!$Q$5:$Q$504,A19,'Demo Pipeline'!$W$5:$W$504,"Attended")) | BF19: =IF(A19="","",COUNTIFS('Demo Pipeline'!$Q$5:$Q$504,A19,'Demo Pipeline'!$X$5:$X$504,"Yes")) | BG19: =IF(A19="","",COUNTIFS('Demo Pipeline'!$Q$5:$Q$504,A19,'Demo Pipeline'!$Y$5:$Y$504,"Closed Won")) | BH19: =IF(A19="","",SUMIFS('Demo Pipeline'!$Z$5:$Z$504,'Demo Pipeline'!$Q$5:$Q$504,A19)) | BI19: =IF(OR(AZ19="",N(AJ19)=0),"",AZ19/AJ19) | BJ19: =IF(OR(BB19="",N(AZ19)=0),"",BB19/AZ19) | BK19: =IF(OR(A19="",N(BB19)=0),"",BD19/BB19) | BL19: =IF(OR(A19="",N(AZ19)=0),"",BD19/AZ19) | BM19: =IF(OR(N(Q19)=0,N(BD19)=0),"",Q19/BD19) | BP19: =IF(OR(AR19="",N(AO19)=0),"",AR19) | BQ19: =IF(OR(AR19="",N(S19)=0),"",S19) | BR19: =IF(AND(ISNUMBER(B19),B19>=Dashboard!$C$4,B19<=Dashboard!$F$4,ISNUMBER(AU19)),AU19+ROW()/10^9,"") | BS19: =IF(AND(ISNUMBER(B19),B19>=Dashboard!$C$4,B19<=Dashboard!$F$4,A19<>""),N(BD19)+N(AU19)/100+ROW()/10^9,"")
